Workbook
Name NativeTimeline_Date: #N/A
Name Slicer_Card_Network: #N/A
Name Slicer_Category: #N/A
Name Slicer_Channel: #N/A
Name Slicer_City: #N/A
Name Slicer_Risk_Level: #N/A

Sheet Sheet1

Sheet Pivot table
A3: Row Labels | B3: Sum of Amount (ZAR)
A4: High | B4: 0.054836871
A5: Low | B5: 0.7437741
A6: Medium | B6: 0.20138903
A7: Grand Total | B7: 1
A20: Row Labels | B20: Sum of Amount (ZAR)
A21: Mr Price | B21: 32706.74
A22: AliExpress | B22: 50150.24
A23: Amazon | B23: 51045.84
A24: South African Airways | B24: 56473.39
A25: Avis | B25: 61370.99
A26: Takealot | B26: 63237.41
A27: Superbalist | B27: 71098.03
A28: Game | B28: 106375.51
A29: Incredible Connection | B29: 161299.1
A30: Makro | B30: 165442.85
A31: Grand Total | B31: 819200.1
A43: Row Labels | B43: Average of Risk_Score
A44: Nedbank | B44: 1.109589
A45: Capitec | B45: 0.96226415
A46: Standard Bank | B46: 0.9527027
A47: ABSA | B47: 0.92405063
A48: FNB | B48: 0.87581699
A49: Grand Total | B49: 0.96747967
A63: Row Labels | B63: Average of Risk_Score | C63: Count of Txn ID | E63: Row Labels | F63: Average of Risk_Score | G63: Count of Txn ID
A64: ATM Withdrawal | B64: 0.7962963 | C64: 54 | E64: ATM Withdrawal | F64: 0.7962963 | G64: 54
A65: Clothing | B65: 1.0588235 | C65: 51 | E65: Clothing | F65: 1.0588235 | G65: 51
A66: Electronics | B66: 1.1489362 | C66: 47 | E66: Electronics | F66: 1.1489362 | G66: 47
A67: Fuel | B67: 0.8625 | C67: 80 | E67: Fuel | F67: 0.8625 | G67: 80
A68: Gambling | B68: 0.84 | C68: 25 | E68: Gambling | F68: 0.84 | G68: 25
A69: Grocery | B69: 1 | C69: 107 | E69: Grocery | F69: 1 | G69: 107
A70: Online Retail | B70: 1 | C70: 96 | E70: Online Retail | F70: 1 | G70: 96
A71: Pharmacy | B71: 0.83333333 | C71: 36 | E71: Pharmacy | F71: 0.83333333 | G71: 36
A72: Restaurant | B72: 0.97368421 | C72: 114 | E72: Restaurant | F72: 0.97368421 | G72: 114
A73: Subscription Services | B73: 0.94339623 | C73: 53 | E73: Subscription Services | F73: 0.94339623 | G73: 53
A74: Travel | B74: 1 | C74: 30 | E74: Travel | F74: 1 | G74: 30
A75: Utilities | B75: 1.0888889 | C75: 45 | E75: Utilities | F75: 1.0888889 | G75: 45
A83: Row Labels | B83: Sum of Risk_Score
A84: Card Not Present (Phone) | B84: 266
A85: Card Present | B85: 85
...

Sheet Dashboard

Sheet Transactions_Cleaned
A1: Txn ID | B1: Card_ID | C1: Date | D1: Time | E1: Merchant | F1: Category | G1: City | H1: Amount (ZAR) | I1: Channel | J1: Status | K1: Notes | L1: Cardholder_name | M1: Credit_Limit | N1: Bank | O1: Card_Network | P1: Percentage-Limit_Utilized | Q1: City_Check | R1: Hour_Check | S1: Velocity_Check | T1: Limit_Check | U1: Category_Check | V1: Channel_Check | W1: Risk_Score | X1: Risk_Level
A2: TXN500001 | B2: CC-10000 | C2: 46068 | D2: 18:47 | E2: Amazon | F2: Online Retail | G2: Gqeberha | H2: 2404.01 | I2: Card Present | J2: Approved | L2: =PROPER(TRIM(SUBSTITUTE(_xlfn.XLOOKUP(B2,Cardholders_Reference!A:A,Cardholders_Reference!B:B),","," "))) -> Carlos Maseko | M2: =_xlfn.XLOOKUP(B2,Cardholders_Reference!A:A,Cardholders_Reference!G:G) -> 25000 | N2: =_xlfn.XLOOKUP(B2,Cardholders_Reference!A:A,Cardholders_Reference!D:D) -> Capitec | O2: =_xlfn.XLOOKUP(B2,Cardholders_Reference!A:A,Cardholders_Reference!E:E) -> Mastercard | P2: =H2/M2 -> 0.0961604 | Q2: =IF(COUNTIFS($B$1:$B$738,B1,$G$1:$G$738,G1)/COUNTIF($B$1:$B$738,B1)<0.5,1,0) -> 0 | R2: =IF(D2="Unknown",1,IF(OR(TIMEVALUE(D2)<TIME(5,0,0),TIMEVALUE(D2)>=TIME(23,0,0)),1,0)) -> 0 | S2: =IF(COUNTIFS($B$1:$B$738,B1,$C$1:$C$738,#REF!)>2,1,0) -> 0 | T2: =IF(P1>0.4,1,0) -> 1 | U2: =IF(OR(F1="Gambling",F1="ATM Withdrawal"),1,0) -> 0 | V2: =IF(OR(I2="Card Not Present (Phone)",I2="Online"),1,0) -> 0 | W2: =SUM(Q2:V2) -> 1 | X2: {=_xlfn.IFS(W2<=1,"Low",W2=2,"Medium",W2>=3,"High")} -> Low
A3: TXN500002 | B3: CC-10000 | C3: 46041 | D3: 13:32 | E3: ABSA ATM | F3: ATM Withdrawal | G3: Gqeberha | H3: 982.64 | I3: Card Present | J3: Approved | L3: =PROPER(TRIM(SUBSTITUTE(_xlfn.XLOOKUP(B3,Cardholders_Reference!A:A,Cardholders_Reference!B:B),","," "))) -> Carlos Maseko | M3: =_xlfn.XLOOKUP(B3,Cardholders_Reference!A:A,Cardholders_Reference!G:G) -> 25000 | N3: =_xlfn.XLOOKUP(B3,Cardholders_Reference!A:A,Cardholders_Reference!D:D) -> Capitec | O3: =_xlfn.XLOOKUP(B3,Cardholders_Reference!A:A,Cardholders_Reference!E:E) -> Mastercard | P3: =H3/M3 -> 0.0393056 | Q3: =IF(COUNTIFS($B$1:$B$738,B2,$G$1:$G$738,G2)/COUNTIF($B$1:$B$738,B2)<0.5,1,0) -> 0 | R3: =IF(D3="Unknown",1,IF(OR(TIMEVALUE(D3)<TIME(5,0,0),TIMEVALUE(D3)>=TIME(23,0,0)),1,0)) -> 0 | S3: =IF(COUNTIFS($B$1:$B$738,B2,$C$1:$C$738,#REF!)>2,1,0) -> 0 | T3: =IF(P2>0.4,1,0) -> 0 | U3: =IF(OR(F2="Gambling",F2="ATM Withdrawal"),1,0) -> 0 | V3: =IF(OR(I3="Card Not Present (Phone)",I3="Online"),1,0) -> 0 | W3: =SUM(Q3:V3) -> 0 | X3: {=_xlfn.IFS(W3<=1,"Low",W3=2,"Medium",W3>=3,"High")} -> Low
A4: TXN500003 | B4: CC-10000 | C4: 46016 | D4: Unknown | E4: Shell | F4: Fuel | G4: Gqeberha | H4: 1017.6 | I4: Card Not Present (Phone) | J4: Approved | L4: =PROPER(TRIM(SUBSTITUTE(_xlfn.XLOOKUP(B4,Cardholders_Reference!A:A,Cardholders_Reference!B:B),","," "))) -> Carlos Maseko | M4: =_xlfn.XLOOKUP(B4,Cardholders_Reference!A:A,Cardholders_Reference!G:G) -> 25000 | N4: =_xlfn.XLOOKUP(B4,Cardholders_Reference!A:A,Cardholders_Reference!D:D) -> Capitec | O4: =_xlfn.XLOOKUP(B4,Cardholders_Reference!A:A,Cardholders_Reference!E:E) -> Mastercard | P4: =H4/M4 -> 0.040704 | Q4: =IF(COUNTIFS($B$1:$B$738,B3,$G$1:$G$738,G3)/COUNTIF($B$1:$B$738,B3)<0.5,1,0) -> 0 | R4: =IF(D4="Unknown",1,IF(OR(TIMEVALUE(D4)<TIME(5,0,0),TIMEVALUE(D4)>=TIME(23,0,0)),1,0)) -> 1 | S4: =IF(COUNTIFS($B$1:$B$738,B3,$C$1:$C$738,#REF!)>2,1,0) -> 0 | T4: =IF(P3>0.4,1,0) -> 0 | U4: =IF(OR(F3="Gambling",F3="ATM Withdrawal"),1,0) -> 1 | V4: =IF(OR(I4="Card Not Present (Phone)",I4="Online"),1,0) -> 1 | W4: =SUM(Q4:V4) -> 3 | X4: {=_xlfn.IFS(W4<=1,"Low",W4=2,"Medium",W4>=3,"High")} -> High
A5: TXN500004 | B5: CC-10000 | C5: 45696 | D5: 15:42 | E5: Amazon | F5: Online Retail | G5: Gqeberha | H5: 982.43 | I5: Card Present | J5: Approved | L5: =PROPER(TRIM(SUBSTITUTE(_xlfn.XLOOKUP(B5,Cardholders_Reference!A:A,Cardholders_Reference!B:B),","," "))) -> Carlos Maseko | M5: =_xlfn.XLOOKUP(B5,Cardholders_Reference!A:A,Cardholders_Reference!G:G) -> 25000 | N5: =_xlfn.XLOOKUP(B5,Cardholders_Reference!A:A,Cardholders_Reference!D:D) -> Capitec | O5: =_xlfn.XLOOKUP(B5,Cardholders_Reference!A:A,Cardholders_Reference!E:E) -> Mastercard | P5: =H5/M5 -> 0.0392972 | Q5: =IF(COUNTIFS($B$1:$B$738,B4,$G$1:$G$738,G4)/COUNTIF($B$1:$B$738,B4)<0.5,1,0) -> 0 | R5: =IF(D5="Unknown",1,IF(OR(TIMEVALUE(D5)<TIME(5,0,0),TIMEVALUE(D5)>=TIME(23,0,0)),1,0)) -> 0 | S5: =IF(COUNTIFS($B$1:$B$738,B4,$C$1:$C$738,#REF!)>2,1,0) -> 0 | T5: =IF(P4>0.4,1,0) -> 0 | U5: =IF(OR(F4="Gambling",F4="ATM Withdrawal"),1,0) -> 0 | V5: =IF(OR(I5="Card Not Present (Phone)",I5="Online"),1,0) -> 0 | W5: =SUM(Q5:V5) -> 0 | X5: {=_xlfn.IFS(W5<=1,"Low",W5=2,"Medium",W5>=3,"High")} -> Low
A6: TXN500005 | B6: CC-10000 | C6: 45661 | D6: 10:47 | E6: BP | F6: Fuel | G6: Gqeberha | H6: 985.17 | I6: Contactless | J6: Approved | L6: =PROPER(TRIM(SUBSTITUTE(_xlfn.XLOOKUP(B6,Cardholders_Reference!A:A,Cardholders_Reference!B:B),","," "))) -> Carlos Maseko | M6: =_xlfn.XLOOKUP(B6,Cardholders_Reference!A:A,Cardholders_Reference!G:G) -> 25000 | N6: =_xlfn.XLOOKUP(B6,Cardholders_Reference!A:A,Cardholders_Reference!D:D) -> Capitec | O6: =_xlfn.XLOOKUP(B6,Cardholders_Reference!A:A,Cardholders_Reference!E:E) -> Mastercard | P6: =H6/M6 -> 0.0394068 | Q6: =IF(COUNTIFS($B$1:$B$738,B5,$G$1:$G$738,G5)/COUNTIF($B$1:$B$738,B5)<0.5,1,0) -> 0 | R6: =IF(D6="Unknown",1,IF(OR(TIMEVALUE(D6)<TIME(5,0,0),TIMEVALUE(D6)>=TIME(23,0,0)),1,0)) -> 0 | S6: =IF(COUNTIFS($B$1:$B$738,B5,$C$1:$C$738,#REF!)>2,1,0) -> 0 | T6: =IF(P5>0.4,1,0) -> 0 | U6: =IF(OR(F5="Gambling",F5="ATM Withdrawal"),1,0) -> 0 | V6: =IF(OR(I6="Card Not Present (Phone)",I6="Online"),1,0) -> 0 | W6: =SUM(Q6:V6) -> 0 | X6: {=_xlfn.IFS(W6<=1,"Low",W6=2,"Medium",W6>=3,"High")} -> Low
A7: TXN500006 | B7: CC-10000 | C7: 46513 | D7: 20:33 | E7: Mugg & Bean | F7: Restaurant | G7: Gqeberha | H7: 123.43 | I7: Card Present | J7: Approved | L7: =PROPER(TRIM(SUBSTITUTE(_xlfn.XLOOKUP(B7,Cardholders_Reference!A:A,Cardholders_Reference!B:B),","," "))) -> Carlos Maseko | M7: =_xlfn.XLOOKUP(B7,Cardholders_Reference!A:A,Cardholders_Reference!G:G) -> 25000 | N7: =_xlfn.XLOOKUP(B7,Cardholders_Reference!A:A,Cardholders_Reference!D:D) -> Capitec | O7: =_xlfn.XLOOKUP(B7,Cardholders_Reference!A:A,Cardholders_Reference!E:E) -> Mastercard | P7: =H7/M7 -> 0.0049372 | Q7: =IF(COUNTIFS($B$1:$B$738,B6,$G$1:$G$738,G6)/COUNTIF($B$1:$B$738,B6)<0.5,1,0) -> 0 | R7: =IF(D7="Unknown",1,IF(OR(TIMEVALUE(D7)<TIME(5,0,0),TIMEVALUE(D7)>=TIME(23,0,0)),1,0)) -> 0 | S7: =IF(COUNTIFS($B$1:$B$738,B6,$C$1:$C$738,#REF!)>2,1,0) -> 0 | T7: =IF(P6>0.4,1,0) -> 0 | U7: =IF(OR(F6="Gambling",F6="ATM Withdrawal"),1,0) -> 0 | V7: =IF(OR(I7="Card Not Present (Phone)",I7="Online"),1,0) -> 0 | W7: =SUM(Q7:V7) -> 0 | X7: {=_xlfn.IFS(W7<=1,"Low",W7=2,"Medium",W7>=3,"High")} -> Low
A8: TXN500007 | B8: CC-10000 | C8: 46193 | D8: 08:27 | E8: Spotify | F8: Subscription Services | G8: Gqeberha | H8: 314.22 | I8: Card Not Present (Phone) | J8: Declined | L8: =PROPER(TRIM(SUBSTITUTE(_xlfn.XLOOKUP(B8,Cardholders_Reference!A:A,Cardholders_Reference!B:B),","," "))) -> Carlos Maseko | M8: =_xlfn.XLOOKUP(B8,Cardholders_Reference!A:A,Cardholders_Reference!G:G) -> 25000 | N8: =_xlfn.XLOOKUP(B8,Cardholders_Reference!A:A,Cardholders_Reference!D:D) -> Capitec | O8: =_xlfn.XLOOKUP(B8,Cardholders_Reference!A:A,Cardholders_Reference!E:E) -> Mastercard | P8: =H8/M8 -> 0.0125688 | Q8: =IF(COUNTIFS($B$1:$B$738,B7,$G$1:$G$738,G7)/COUNTIF($B$1:$B$738,B7)<0.5,1,0) -> 0 | R8: =IF(D8="Unknown",1,IF(OR(TIMEVALUE(D8)<TIME(5,0,0),TIMEVALUE(D8)>=TIME(23,0,0)),1,0)) -> 0 | S8: =IF(COUNTIFS($B$1:$B$738,B7,$C$1:$C$738,#REF!)>2,1,0) -> 0 | T8: =IF(P7>0.4,1,0) -> 0 | U8: =IF(OR(F7="Gambling",F7="ATM Withdrawal"),1,0) -> 0 | V8: =IF(OR(I8="Card Not Present (Phone)",I8="Online"),1,0) -> 1 | W8: =SUM(Q8:V8) -> 1 | X8: {=_xlfn.IFS(W8<=1,"Low",W8=2,"Medium",W8>=3,"High")} -> Low
A9: TXN500008 | B9: CC-10000 | C9: 45931 | D9: 07:49 | E9: Engen | F9: Fuel | G9: Gqeberha | H9: 979.18 | I9: Contactless | J9: Approved | L9: =PROPER(TRIM(SUBSTITUTE(_xlfn.XLOOKUP(B9,Cardholders_Reference!A:A,Cardholders_Reference!B:B),","," "))) -> Carlos Maseko | M9: =_xlfn.XLOOKUP(B9,Cardholders_Reference!A:A,Cardholders_Reference!G:G) -> 25000 | N9: =_xlfn.XLOOKUP(B9,Cardholders_Reference!A:A,Cardholders_Reference!D:D) -> Capitec | O9: =_xlfn.XLOOKUP(B9,Cardholders_Reference!A:A,Cardholders_Reference!E:E) -> Mastercard | P9: =H9/M9 -> 0.0391672 | Q9: =IF(COUNTIFS($B$1:$B$738,B8,$G$1:$G$738,G8)/COUNTIF($B$1:$B$738,B8)<0.5,1,0) -> 0 | R9: =IF(D9="Unknown",1,IF(OR(TIMEVALUE(D9)<TIME(5,0,0),TIMEVALUE(D9)>=TIME(23,0,0)),1,0)) -> 0 | S9: =IF(COUNTIFS($B$1:$B$738,B8,$C$1:$C$738,#REF!)>2,1,0) -> 0 | T9: =IF(P8>0.4,1,0) -> 0 | U9: =IF(OR(F8="Gambling",F8="ATM Withdrawal"),1,0) -> 0 | V9: =IF(OR(I9="Card Not Present (Phone)",I9="Online"),1,0) -> 0 | W9: =SUM(Q9:V9) -> 0 | X9: {=_xlfn.IFS(W9<=1,"Low",W9=2,"Medium",W9>=3,"High")} -> Low
A10: TXN500009 | B10: CC-10000 | C10: 45727 | D10: 14:27 | E10: MTN | F10: Utilities | G10: Cape Town | H10: 1222.89 | I10: Contactless | J10: Approved | L10: =PROPER(TRIM(SUBSTITUTE(_xlfn.XLOOKUP(B10,Cardholders_Reference!A:A,Cardholders_Reference!B:B),","," "))) -> Carlos Maseko | M10: =_xlfn.XLOOKUP(B10,Cardholders_Reference!A:A,Cardholders_Reference!G:G) -> 25000 | N10: =_xlfn.XLOOKUP(B10,Cardholders_Reference!A:A,Cardholders_Reference!D:D) -> Capitec | O10: =_xlfn.XLOOKUP(B10,Cardholders_Reference!A:A,Cardholders_Reference!E:E) -> Mastercard | P10: =H10/M10 -> 0.0489156 | Q10: =IF(COUNTIFS($B$1:$B$738,B9,$G$1:$G$738,G9)/COUNTIF($B$1:$B$738,B9)<0.5,1,0) -> 0 | R10: =IF(D10="Unknown",1,IF(OR(TIMEVALUE(D10)<TIME(5,0,0),TIMEVALUE(D10)>=TIME(23,0,0)),1,0)) -> 0 | S10: =IF(COUNTIFS($B$1:$B$738,B9,$C$1:$C$738,#REF!)>2,1,0) -> 0 | T10: =IF(P9>0.4,1,0) -> 0 | U10: =IF(OR(F9="Gambling",F9="ATM Withdrawal"),1,0) -> 0 | V10: =IF(OR(I10="Card Not Present (Phone)",I10="Online"),1,0) -> 0 | W10: =SUM(Q10:V10) -> 0 | X10: {=_xlfn.IFS(W10<=1,"Low",W10=2,"Medium",W10>=3,"High")} -> Low
A11: TXN500010 | B11: CC-10000 | C11: 46085 | D11: 13:55 | E11: Spar | F11: Grocery | G11: Gqeberha | H11: 880.73 | I11: Contactless | J11: Approved | L11: =PROPER(TRIM(SUBSTITUTE(_xlfn.XLOOKUP(B11,Cardholders_Reference!A:A,Cardholders_Reference!B:B),","," "))) -> Carlos Maseko | M11: =_xlfn.XLOOKUP(B11,Cardholders_Reference!A:A,Cardholders_Reference!G:G) -> 25000 | N11: =_xlfn.XLOOKUP(B11,Cardholders_Reference!A:A,Cardholders_Reference!D:D) -> Capitec | O11: =_xlfn.XLOOKUP(B11,Cardholders_Reference!A:A,Cardholders_Reference!E:E) -> Mastercard | P11: =H11/M11 -> 0.0352292 | Q11: =IF(COUNTIFS($B$1:$B$738,B10,$G$1:$G$738,G10)/COUNTIF($B$1:$B$738,B10)<0.5,1,0) -> 1 | R11: =IF(D11="Unknown",1,IF(OR(TIMEVALUE(D11)<TIME(5,0,0),TIMEVALUE(D11)>=TIME(23,0,0)),1,0)) -> 0 | S11: =IF(COUNTIFS($B$1:$B$738,B10,$C$1:$C$738,#REF!)>2,1,0) -> 0 | T11: =IF(P10>0.4,1,0) -> 0 | U11: =IF(OR(F10="Gambling",F10="ATM Withdrawal"),1,0) -> 0 | V11: =IF(OR(I11="Card Not Present (Phone)",I11="Online"),1,0) -> 0 | W11: =SUM(Q11:V11) -> 1 | X11: {=_xlfn.IFS(W11<=1,"Low",W11=2,"Medium",W11>=3,"High")} -> Low
A12: TXN500011 | B12: CC-10001 | C12: 45935 | D12: 11:15 | E12: Mr Delivery | F12: Restaurant | G12: Gqeberha | H12: 562.54 | I12: Card Not Present (Phone) | J12: Approved | L12: =PROPER(TRIM(SUBSTITUTE(_xlfn.XLOOKUP(B12,Cardholders_Reference!A:A,Cardholders_Reference!B:B),","," "))) -> Fatima Adams | M12: =_xlfn.XLOOKUP(B12,Cardholders_Reference!A:A,Cardholders_Reference!G:G) -> 20000 | N12: =_xlfn.XLOOKUP(B12,Cardholders_Reference!A:A,Cardholders_Reference!D:D) -> Standard Bank | O12: =_xlfn.XLOOKUP(B12,Cardholders_Reference!A:A,Cardholders_Reference!E:E) -> Visa | P12: =H12/M12 -> 0.028127 | Q12: =IF(COUNTIFS($B$1:$B$738,B11,$G$1:$G$738,G11)/COUNTIF($B$1:$B$738,B11)<0.5,1,0) -> 0 | R12: =IF(D12="Unknown",1,IF(OR(TIMEVALUE(D12)<TIME(5,0,0),TIMEVALUE(D12)>=TIME(23,0,0)),1,0)) -> 0 | S12: =IF(COUNTIFS($B$1:$B$738,B11,$C$1:$C$738,#REF!)>2,1,0) -> 0 | T12: =IF(P11>0.4,1,0) -> 0 | U12: =IF(OR(F11="Gambling",F11="ATM Withdrawal"),1,0) -> 0 | V12: =IF(OR(I12="Card Not Present (Phone)",I12="Online"),1,0) -> 1 | W12: =SUM(Q12:V12) -> 1 | X12: {=_xlfn.IFS(W12<=1,"Low",W12=2,"Medium",W12>=3,"High")} -> Low
A13: TXN500012 | B13: CC-10001 | C13: 46150 | D13: 13:56 | E13: FlySafair | F13: Travel | G13: Gqeberha | H13: 5562.16 | I13: Card Present | J13: Approved | L13: =PROPER(TRIM(SUBSTITUTE(_xlfn.XLOOKUP(B13,Cardholders_Reference!A:A,Cardholders_Reference!B:B),","," "))) -> Fatima Adams | M13: =_xlfn.XLOOKUP(B13,Cardholders_Reference!A:A,Cardholders_Reference!G:G) -> 20000 | N13: =_xlfn.XLOOKUP(B13,Cardholders_Reference!A:A,Cardholders_Reference!D:D) -> Standard Bank | O13: =_xlfn.XLOOKUP(B13,Cardholders_Reference!A:A,Cardholders_Reference!E:E) -> Visa | P13: =H13/M13 -> 0.278108 | Q13: =IF(COUNTIFS($B$1:$B$738,B12,$G$1:$G$738,G12)/COUNTIF($B$1:$B$738,B12)<0.5,1,0) -> 0 | R13: =IF(D13="Unknown",1,IF(OR(TIMEVALUE(D13)<TIME(5,0,0),TIMEVALUE(D13)>=TIME(23,0,0)),1,0)) -> 0 | S13: =IF(COUNTIFS($B$1:$B$738,B12,$C$1:$C$738,#REF!)>2,1,0) -> 0 | T13: =IF(P12>0.4,1,0) -> 0 | U13: =IF(OR(F12="Gambling",F12="ATM Withdrawal"),1,0) -> 0 | V13: =IF(OR(I13="Card Not Present (Phone)",I13="Online"),1,0) -> 0 | W13: =SUM(Q13:V13) -> 0 | X13: {=_xlfn.IFS(W13<=1,"Low",W13=2,"Medium",W13>=3,"High")} -> Low
... A39: TXN500038 | B39: CC-10002 | C39: 45734 | D39: 15:10 | E39: Showmax | F39: Subscription Services | G39: Pretoria | H39: 435.24 | I39: Card Present | J39: Approved | L39: =PROPER(TRIM(SUBSTITUTE(_xlfn.XLOOKUP(B39,Cardholders_Reference!A:A,Cardholders_Reference!B:B),","," "))) -> Mahlangu Lerato | M39: =_xlfn.XLOOKUP(B39,Cardholders_Reference!A:A,Cardholders_Reference!G:G) -> 100000 | N39: =_xlfn.XLOOKUP(B39,Cardholders_Reference!A:A,Cardholders_Reference!D:D) -> Capitec | O39: =_xlfn.XLOOKUP(B39,Cardholders_Reference!A:A,Cardholders_Reference!E:E) -> Visa | P39: =H39/M39 -> 0.0043524 | Q39: =IF(COUNTIFS($B$1:$B$738,B38,$G$1:$G$738,G38)/COUNTIF($B$1:$B$738,B38)<0.5,1,0) -> 0 | R39: =IF(D39="Unknown",1,IF(OR(TIMEVALUE(D39)<TIME(5,0,0),TIMEVALUE(D39)>=TIME(23,0,0)),1,0)) -> 0 | S39: =IF(COUNTIFS($B$1:$B$738,B38,$C$1:$C$738,#REF!)>2,1,0) -> 0 | T39: =IF(P38>0.4,1,0) -> 0 | U39: =IF(OR(F38="Gambling",F38="ATM Withdrawal"),1,0) -> 1 | V39: =IF(OR(I39="Card Not Present (Phone)",I39="Online"),1,0) -> 0 | W39: =SUM(Q39:V39) -> 1 | X39: {=_xlfn.IFS(W39<=1,"Low",W39=2,"Medium",W39>=3,"High")} -> Low
A40: TXN500039 | B40: CC-10002 | C40: 45828 | D40: 09:29 | E40: Pick n Pay | F40: Grocery | G40: Pretoria | H40: 378.11 | I40: Contactless | J40: Declined | K40: verified via OTP call | L40: =PROPER(TRIM(SUBSTITUTE(_xlfn.XLOOKUP(B40,Cardholders_Reference!A:A,Cardholders_Reference!B:B),","," "))) -> Mahlangu Lerato | M40: =_xlfn.XLOOKUP(B40,Cardholders_Reference!A:A,Cardholders_Reference!G:G) -> 100000 | N40: =_xlfn.XLOOKUP(B40,Cardholders_Reference!A:A,Cardholders_Reference!D:D) -> Capitec | O40: =_xlfn.XLOOKUP(B40,Cardholders_Reference!A:A,Cardholders_Reference!E:E) -> Visa | P40: =H40/M40 -> 0.0037811 | Q40: =IF(COUNTIFS($B$1:$B$738,B39,$G$1:$G$738,G39)/COUNTIF($B$1:$B$738,B39)<0.5,1,0) -> 0 | R40: =IF(D40="Unknown",1,IF(OR(TIMEVALUE(D40)<TIME(5,0,0),TIMEVALUE(D40)>=TIME(23,0,0)),1,0)) -> 0 | S40: =IF(COUNTIFS($B$1:$B$738,B39,$C$1:$C$738,#REF!)>2,1,0) -> 0 | T40: =IF(P39>0.4,1,0) -> 0 | U40: =IF(OR(F39="Gambling",F39="ATM Withdrawal"),1,0) -> 0 | V40: =IF(OR(I40="Card Not Present (Phone)",I40="Online"),1,0) -> 0 | W40: =SUM(Q40:V40) -> 0 | X40: {=_xlfn.IFS(W40<=1,"Low",W40=2,"Medium",W40>=3,"High")} -> Low
A41: TXN500040 | B41: CC-10003 | C41: 45766 | D41: 19:11 | E41: Amazon | F41: Online Retail | G41: Cape Town | H41: 429.93 | I41: Card Present | J41: Approved | L41: =PROPER(TRIM(SUBSTITUTE(_xlfn.XLOOKUP(B41,Cardholders_Reference!A:A,Cardholders_Reference!B:B),","," "))) -> Lerato Dlamini | M41: =_xlfn.XLOOKUP(B41,Cardholders_Reference!A:A,Cardholders_Reference!G:G) -> 30000 | N41: =_xlfn.XLOOKUP(B41,Cardholders_Reference!A:A,Cardholders_Reference!D:D) -> Nedbank | O41: =_xlfn.XLOOKUP(B41,Cardholders_Reference!A:A,Cardholders_Reference!E:E) -> Visa | P41: =H41/M41 -> 0.014331 | Q41: =IF(COUNTIFS($B$1:$B$738,B40,$G$1:$G$738,G40)/COUNTIF($B$1:$B$738,B40)<0.5,1,0) -> 1 | R41: =IF(D41="Unknown",1,IF(OR(TIMEVALUE(D41)<TIME(5,0,0),TIMEVALUE(D41)>=TIME(23,0,0)),1,0)) -> 0 | S41: =IF(COUNTIFS($B$1:$B$738,B40,$C$1:$C$738,#REF!)>2,1,0) -> 0 | T41: =IF(P40>0.4,1,0) -> 0 | U41: =IF(OR(F40="Gambling",F40="ATM Withdrawal"),1,0) -> 0 | V41: =IF(OR(I41="Card Not Present (Phone)",I41="Online"),1,0) -> 0 | W41: =SUM(Q41:V41) -> 1 | X41: {=_xlfn.IFS(W41<=1,"Low",W41=2,"Medium",W41>=3,"High")} -> Low
A42: TXN500041 | B42: CC-10003 | C42: 46073 | D42: 20:48 | E42: Superbalist | F42: Online Retail | G42: Cape Town | H42: 3748 | I42: Card Present | J42: Declined | L42: =PROPER(TRIM(SUBSTITUTE(_xlfn.XLOOKUP(B42,Cardholders_Reference!A:A,Cardholders_Reference!B:B),","," "))) -> Lerato Dlamini | M42: =_xlfn.XLOOKUP(B42,Cardholders_Reference!A:A,Cardholders_Reference!G:G) -> 30000 | N42: =_xlfn.XLOOKUP(B42,Cardholders_Reference!A:A,Cardholders_Reference!D:D) -> Nedbank | O42: =_xlfn.XLOOKUP(B42,Cardholders_Reference!A:A,Cardholders_Reference!E:E) -> Visa | P42: =H42/M42 -> 0.12493333 | Q42: =IF(COUNTIFS($B$1:$B$738,B41,$G$1:$G$738,G41)/COUNTIF($B$1:$B$738,B41)<0.5,1,0) -> 1 | R42: =IF(D42="Unknown",1,IF(OR(TIMEVALUE(D42)<TIME(5,0,0),TIMEVALUE(D42)>=TIME(23,0,0)),1,0)) -> 0 | S42: =IF(COUNTIFS($B$1:$B$738,B41,$C$1:$C$738,#REF!)>2,1,0) -> 0 | T42: =IF(P41>0.4,1,0) -> 0 | U42: =IF(OR(F41="Gambling",F41="ATM Withdrawal"),1,0) -> 0 | V42: =IF(OR(I42="Card Not Present (Phone)",I42="Online"),1,0) -> 0 | W42: =SUM(Q42:V42) -> 1 | X42: {=_xlfn.IFS(W42<=1,"Low",W42=2,"Medium",W42>=3,"High")} -> Low
A43: TXN500042 | B43: CC-10003 | C43: 46067 | D43: 07:20 | E43: Showmax | F43: Subscription Services | G43: Cape Town | H43: 362.52 | I43: Card Not Present (Phone) | J43: Approved | L43: =PROPER(TRIM(SUBSTITUTE(_xlfn.XLOOKUP(B43,Cardholders_Reference!A:A,Cardholders_Reference!B:B),","," "))) -> Lerato Dlamini | M43: =_xlfn.XLOOKUP(B43,Cardholders_Reference!A:A,Cardholders_Reference!G:G) -> 30000 | N43: =_xlfn.XLOOKUP(B43,Cardholders_Reference!A:A,Cardholders_Reference!D:D) -> Nedbank | O43: =_xlfn.XLOOKUP(B43,Cardholders_Reference!A:A,Cardholders_Reference!E:E) -> Visa | P43: =H43/M43 -> 0.012084 | Q43: =IF(COUNTIFS($B$1:$B$738,B42,$G$1:$G$738,G42)/COUNTIF($B$1:$B$738,B42)<0.5,1,0) -> 0 | R43: =IF(D43="Unknown",1,IF(OR(TIMEVALUE(D43)<TIME(5,0,0),TIMEVALUE(D43)>=TIME(23,0,0)),1,0)) -> 0 | S43: =IF(COUNTIFS($B$1:$B$738,B42,$C$1:$C$738,#REF!)>2,1,0) -> 0 | T43: =IF(P42>0.4,1,0) -> 0 | U43: =IF(OR(F42="Gambling",F42="ATM Withdrawal"),1,0) -> 0 | V43: =IF(OR(I43="Card Not Present (Phone)",I43="Online"),1,0) -> 1 | W43: =SUM(Q43:V43) -> 1 | X43: {=_xlfn.IFS(W43<=1,"Low",W43=2,"Medium",W43>=3,"High")} -> Low
A44: TXN500043 | B44: CC-10003 | C44: 46024 | D44: 22:44 | E44: Pick n Pay | F44: Grocery | G44: Cape Town | H44: 1701.4 | I44: Card Present | J44: Approved | L44: =PROPER(TRIM(SUBSTITUTE(_xlfn.XLOOKUP(B44,Cardholders_Reference!A:A,Cardholders_Reference!B:B),","," "))) -> Lerato Dlamini | M44: =_xlfn.XLOOKUP(B44,Cardholders_Reference!A:A,Cardholders_Reference!G:G) -> 30000 | N44: =_xlfn.XLOOKUP(B44,Cardholders_Reference!A:A,Cardholders_Reference!D:D) -> Nedbank | O44: =_xlfn.XLOOKUP(B44,Cardholders_Reference!A:A,Cardholders_Reference!E:E) -> Visa | P44: =H44/M44 -> 0.056713333 | Q44: =IF(COUNTIFS($B$1:$B$738,B43,$G$1:$G$738,G43)/COUNTIF($B$1:$B$738,B43)<0.5,1,0) -> 0 | R44: =IF(D44="Unknown",1,IF(OR(TIMEVALUE(D44)<TIME(5,0,0),TIMEVALUE(D44)>=TIME(23,0,0)),1,0)) -> 0 | S44: =IF(COUNTIFS($B$1:$B$738,B43,$C$1:$C$738,#REF!)>2,1,0) -> 0 | T44: =IF(P43>0.4,1,0) -> 0 | U44: =IF(OR(F43="Gambling",F43="ATM Withdrawal"),1,0) -> 0 | V44: =IF(OR(I44="Card Not Present (Phone)",I44="Online"),1,0) -> 0 | W44: =SUM(Q44:V44) -> 0 | X44: {=_xlfn.IFS(W44<=1,"Low",W44=2,"Medium",W44>=3,"High")} -> Low
A45: TXN500044 | B45: CC-10003 | C45: 46072 | D45: 10:57 | E45: Spar | F45: Grocery | G45: Cape Town | H45: 1605.59 | I45: Contactless | J45: Approved | L45: =PROPER(TRIM(SUBSTITUTE(_xlfn.XLOOKUP(B45,Cardholders_Reference!A:A,Cardholders_Reference!B:B),","," "))) -> Lerato Dlamini | M45: =_xlfn.XLOOKUP(B45,Cardholders_Reference!A:A,Cardholders_Reference!G:G) -> 30000 | N45: =_xlfn.XLOOKUP(B45,Cardholders_Reference!A:A,Cardholders_Reference!D:D) -> Nedbank | O45: =_xlfn.XLOOKUP(B45,Cardholders_Reference!A:A,Cardholders_Reference!E:E) -> Visa | P45: =H45/M45 -> 0.053519667 | Q45: =IF(COUNTIFS($B$1:$B$738,B44,$G$1:$G$738,G44)/COUNTIF($B$1:$B$738,B44)<0.5,1,0) -> 0 | R45: =IF(D45="Unknown",1,IF(OR(TIMEVALUE(D45)<TIME(5,0,0),TIMEVALUE(D45)>=TIME(23,0,0)),1,0)) -> 0 | S45: =IF(COUNTIFS($B$1:$B$738,B44,$C$1:$C$738,#REF!)>2,1,0) -> 0 | T45: =IF(P44>0.4,1,0) -> 0 | U45: =IF(OR(F44="Gambling",F44="ATM Withdrawal"),1,0) -> 0 | V45: =IF(OR(I45="Card Not Present (Phone)",I45="Online"),1,0) -> 0 | W45: =SUM(Q45:V45) -> 0 | X45: {=_xlfn.IFS(W45<=1,"Low",W45=2,"Medium",W45>=3,"High")} -> Low
A46: TXN500045 | B46: CC-10003 | C46: 45731 | D46: 21:52 | E46: Nandos | F46: Restaurant | G46: Cape Town | H46: 106.16 | I46: Card Present | J46: Approved | L46: =PROPER(TRIM(SUBSTITUTE(_xlfn.XLOOKUP(B46,Cardholders_Reference!A:A,Cardholders_Reference!B:B),","," "))) -> Lerato Dlamini | M46: =_xlfn.XLOOKUP(B46,Cardholders_Reference!A:A,Cardholders_Reference!G:G) -> 30000 | N46: =_xlfn.XLOOKUP(B46,Cardholders_Reference!A:A,Cardholders_Reference!D:D) -> Nedbank | O46: =_xlfn.XLOOKUP(B46,Cardholders_Reference!A:A,Cardholders_Reference!E:E) -> Visa | P46: =H46/M46 -> 0.0035386667 | Q46: =IF(COUNTIFS($B$1:$B$738,B45,$G$1:$G$738,G45)/COUNTIF($B$1:$B$738,B45)<0.5,1,0) -> 0 | R46: =IF(D46="Unknown",1,IF(OR(TIMEVALUE(D46)<TIME(5,0,0),TIMEVALUE(D46)>=TIME(23,0,0)),1,0)) -> 0 | S46: =IF(COUNTIFS($B$1:$B$738,B45,$C$1:$C$738,#REF!)>2,1,0) -> 0 | T46: =IF(P45>0.4,1,0) -> 0 | U46: =IF(OR(F45="Gambling",F45="ATM Withdrawal"),1,0) -> 0 | V46: =IF(OR(I46="Card Not Present (Phone)",I46="Online"),1,0) -> 0 | W46: =SUM(Q46:V46) -> 0 | X46: {=_xlfn.IFS(W46<=1,"Low",W46=2,"Medium",W46>=3,"High")} -> Low
A47: TXN500046 | B47: CC-10003 | C47: 46207 | D47: 13:18 | E47: Clicks | F47: Pharmacy | G47: Cape Town | H47: 814.43 | I47: Card Present | J47: Approved | L47: =PROPER(TRIM(SUBSTITUTE(_xlfn.XLOOKUP(B47,Cardholders_Reference!A:A,Cardholders_Reference!B:B),","," "))) -> Lerato Dlamini | M47: =_xlfn.XLOOKUP(B47,Cardholders_Reference!A:A,Cardholders_Reference!G:G) -> 30000 | N47: =_xlfn.XLOOKUP(B47,Cardholders_Reference!A:A,Cardholders_Reference!D:D) -> Nedbank | O47: =_xlfn.XLOOKUP(B47,Cardholders_Reference!A:A,Cardholders_Reference!E:E) -> Visa | P47: =H47/M47 -> 0.027147667 | Q47: =IF(COUNTIFS($B$1:$B$738,B46,$G$1:$G$738,G46)/COUNTIF($B$1:$B$738,B46)<0.5,1,0) -> 0 | R47: =IF(D47="Unknown",1,IF(OR(TIMEVALUE(D47)<TIME(5,0,0),TIMEVALUE(D47)>=TIME(23,0,0)),1,0)) -> 0 | S47: =IF(COUNTIFS($B$1:$B$738,B46,$C$1:$C$738,#REF!)>2,1,0) -> 0 | T47: =IF(P46>0.4,1,0) -> 0 | U47: =IF(OR(F46="Gambling",F46="ATM Withdrawal"),1,0) -> 0 | V47: =IF(OR(I47="Card Not Present (Phone)",I47="Online"),1,0) -> 0 | W47: =SUM(Q47:V47) -> 0 | X47: {=_xlfn.IFS(W47<=1,"Low",W47=2,"Medium",W47>=3,"High")} -> Low
A48: TXN500047 | B48: CC-10003 | C48: 45709 | D48: 10:19 | E48: MTN | F48: Utilities | G48: Durban | H48: 1611.95 | I48: Online | J48: Approved | L48: =PROPER(TRIM(SUBSTITUTE(_xlfn.XLOOKUP(B48,Cardholders_Reference!A:A,Cardholders_Reference!B:B),","," "))) -> Lerato Dlamini | M48: =_xlfn.XLOOKUP(B48,Cardholders_Reference!A:A,Cardholders_Reference!G:G) -> 30000 | N48: =_xlfn.XLOOKUP(B48,Cardholders_Reference!A:A,Cardholders_Reference!D:D) -> Nedbank | O48: =_xlfn.XLOOKUP(B48,Cardholders_Reference!A:A,Cardholders_Reference!E:E) -> Visa | P48: =H48/M48 -> 0.053731667 | Q48: =IF(COUNTIFS($B$1:$B$738,B47,$G$1:$G$738,G47)/COUNTIF($B$1:$B$738,B47)<0.5,1,0) -> 1 | R48: =IF(D48="Unknown",1,IF(OR(TIMEVALUE(D48)<TIME(5,0,0),TIMEVALUE(D48)>=TIME(23,0,0)),1,0)) -> 0 | S48: =IF(COUNTIFS($B$1:$B$738,B47,$C$1:$C$738,#REF!)>2,1,0) -> 0 | T48: =IF(P47>0.4,1,0) -> 0 | U48: =IF(OR(F47="Gambling",F47="ATM Withdrawal"),1,0) -> 0 | V48: =IF(OR(I48="Card Not Present (Phone)",I48="Online"),1,0) -> 1 | W48: =SUM(Q48:V48) -> 2 | X48: {=_xlfn.IFS(W48<=1,"Low",W48=2,"Medium",W48>=3,"High")} -> Medium
A49: TXN500048 | B49: CC-10003 | C49: 45770 | D49: 13:17 | E49: Shell | F49: Fuel | G49: Cape Town | H49: 1011.44 | I49: Card Not Present (Phone) | J49: Declined | L49: =PROPER(TRIM(SUBSTITUTE(_xlfn.XLOOKUP(B49,Cardholders_Reference!A:A,Cardholders_Reference!B:B),","," "))) -> Lerato Dlamini | M49: =_xlfn.XLOOKUP(B49,Cardholders_Reference!A:A,Cardholders_Reference!G:G) -> 30000 | N49: =_xlfn.XLOOKUP(B49,Cardholders_Reference!A:A,Cardholders_Reference!D:D) -> Nedbank | O49: =_xlfn.XLOOKUP(B49,Cardholders_Reference!A:A,Cardholders_Reference!E:E) -> Visa | P49: =H49/M49 -> 0.033714667 | Q49: =IF(COUNTIFS($B$1:$B$738,B48,$G$1:$G$738,G48)/COUNTIF($B$1:$B$738,B48)<0.5,1,0) -> 1 | R49: =IF(D49="Unknown",1,IF(OR(TIMEVALUE(D49)<TIME(5,0,0),TIMEVALUE(D49)>=TIME(23,0,0)),1,0)) -> 0 | S49: =IF(COUNTIFS($B$1:$B$738,B48,$C$1:$C$738,#REF!)>2,1,0) -> 0 | T49: =IF(P48>0.4,1,0) -> 0 | U49: =IF(OR(F48="Gambling",F48="ATM Withdrawal"),1,0) -> 0 | V49: =IF(OR(I49="Card Not Present (Phone)",I49="Online"),1,0) -> 1 | W49: =SUM(Q49:V49) -> 2 | X49: {=_xlfn.IFS(W49<=1,"Low",W49=2,"Medium",W49>=3,"High")} -> Medium
A50: TXN500049 | B50: CC-10003 | C50: 45830 | D50: Unknown | E50: Checkers | F50: Grocery | G50: Cape Town | H50: 876.57 | I50: Card Present | J50: Declined | L50: =PROPER(TRIM(SUBSTITUTE(_xlfn.XLOOKUP(B50,Cardholders_Reference!A:A,Cardholders_Reference!B:B),","," "))) -> Lerato Dlamini | M50: =_xlfn.XLOOKUP(B50,Cardholders_Reference!A:A,Cardholders_Reference!G:G) -> 30000 | N50: =_xlfn.XLOOKUP(B50,Cardholders_Reference!A:A,Cardholders_Reference!D:D) -> Nedbank | O50: =_xlfn.XLOOKUP(B50,Cardholders_Reference!A:A,Cardholders_Reference!E:E) -> Visa | P50: =H50/M50 -> 0.029219 | Q50: =IF(COUNTIFS($B$1:$B$738,B49,$G$1:$G$738,G49)/COUNTIF($B$1:$B$738,B49)<0.5,1,0) -> 1 | R50: =IF(D50="Unknown",1,IF(OR(TIMEVALUE(D50)<TIME(5,0,0),TIMEVALUE(D50)>=TIME(23,0,0)),1,0)) -> 1 | S50: =IF(COUNTIFS($B$1:$B$738,B49,$C$1:$C$738,#REF!)>2,1,0) -> 0 | T50: =IF(P49>0.4,1,0) -> 0 | U50: =IF(OR(F49="Gambling",F49="ATM Withdrawal"),1,0) -> 0 | V50: =IF(OR(I50="Card Not Present (Phone)",I50="Online"),1,0) -> 0 | W50: =SUM(Q50:V50) -> 2 | X50: {=_xlfn.IFS(W50<=1,"Low",W50=2,"Medium",W50>=3,"High")} -> Medium
A51: TXN500050 | B51: CC-10003 | C51: 46785 | D51: 09:10 | E51: Amazon | F51: Online Retail | G51: Cape Town | H51: 3357.01 | I51: Card Present | J51: Approved | L51: =PROPER(TRIM(SUBSTITUTE(_xlfn.XLOOKUP(B51,Cardholders_Reference!A:A,Cardholders_Reference!B:B),","," "))) -> Lerato Dlamini | M51: =_xlfn.XLOOKUP(B51,Cardholders_Reference!A:A,Cardholders_Reference!G:G) -> 30000 | N51: =_xlfn.XLOOKUP(B51,Cardholders_Reference!A:A,Cardholders_Reference!D:D) -> Nedbank | O51: =_xlfn.XLOOKUP(B51,Cardholders_Reference!A:A,Cardholders_Reference!E:E) -> Visa | P51: =H51/M51 -> 0.11190033 | Q51: =IF(COUNTIFS($B$1:$B$738,B50,$G$1:$G$738,G50)/COUNTIF($B$1:$B$738,B50)<0.5,1,0) -> 0 | R51: =IF(D51="Unknown",1,IF(OR(TIMEVALUE(D51)<TIME(5,0,0),TIMEVALUE(D51)>=TIME(23,0,0)),1,0)) -> 0 | S51: =IF(COUNTIFS($B$1:$B$738,B50,$C$1:$C$738,#REF!)>2,1,0) -> 0 | T51: =IF(P50>0.4,1,0) -> 0 | U51: =IF(OR(F50="Gambling",F50="ATM Withdrawal"),1,0) -> 0 | V51: =IF(OR(I51="Card Not Present (Phone)",I51="Online"),1,0) -> 0 | W51: =SUM(Q51:V51) -> 0 | X51: {=_xlfn.IFS(W51<=1,"Low",W51=2,"Medium",W51>=3,"High")} -> Low
A52: TXN500051 | B52: CC-10003 | C52: 46023 | D52: 22:03 | E52: Total | F52: Fuel | G52: Cape Town | H52: 588.72 | I52: Contactless | J52: Approved | L52: =PROPER(TRIM(SUBSTITUTE(_xlfn.XLOOKUP(B52,Cardholders_Reference!A:A,Cardholders_Reference!B:B),","," "))) -> Lerato Dlamini | M52: =_xlfn.XLOOKUP(B52,Cardholders_Reference!A:A,Cardholders_Reference!G:G) -> 30000 | N52: =_xlfn.XLOOKUP(B52,Cardholders_Reference!A:A,Cardholders_Reference!D:D) -> Nedbank | O52: =_xlfn.XLOOKUP(B52,Cardholders_Reference!A:A,Cardholders_Reference!E:E) -> Visa | P52: =H52/M52 -> 0.019624 | Q52: =IF(COUNTIFS($B$1:$B$738,B51,$G$1:$G$738,G51)/COUNTIF($B$1:$B$738,B51)<0.5,1,0) -> 1 | R52: =IF(D52="Unknown",1,IF(OR(TIMEVALUE(D52)<TIME(5,0,0),TIMEVALUE(D52)>=TIME(23,0,0)),1,0)) -> 0 | S52: =IF(COUNTIFS($B$1:$B$738,B51,$C$1:$C$738,#REF!)>2,1,0) -> 0 | T52: =IF(P51>0.4,1,0) -> 0 | U52: =IF(OR(F51="Gambling",F51="ATM Withdrawal"),1,0) -> 0 | V52: =IF(OR(I52="Card Not Present (Phone)",I52="Online"),1,0) -> 0 | W52: =SUM(Q52:V52) -> 1 | X52: {=_xlfn.IFS(W52<=1,"Low",W52=2,"Medium",W52>=3,"High")} -> Low
... A56: TXN500055 | B56: CC-10004 | C56: 45988 | D56: 15:48 | E56: FNB ATM | F56: ATM Withdrawal | G56: Johannesburg | H56: 1260.81 | I56: Online | J56: Approved | L56: =PROPER(TRIM(SUBSTITUTE(_xlfn.XLOOKUP(B56,Cardholders_Reference!A:A,Cardholders_Reference!B:B),","," "))) -> Rachel Sithole | M56: =_xlfn.XLOOKUP(B56,Cardholders_Reference!A:A,Cardholders_Reference!G:G) -> 20000 | N56: =_xlfn.XLOOKUP(B56,Cardholders_Reference!A:A,Cardholders_Reference!D:D) -> FNB | O56: =_xlfn.XLOOKUP(B56,Cardholders_Reference!A:A,Cardholders_Reference!E:E) -> Mastercard | P56: =H56/M56 -> 0.0630405 | Q56: =IF(COUNTIFS($B$1:$B$738,B55,$G$1:$G$738,G55)/COUNTIF($B$1:$B$738,B55)<0.5,1,0) -> 0 | R56: =IF(D56="Unknown",1,IF(OR(TIMEVALUE(D56)<TIME(5,0,0),TIMEVALUE(D56)>=TIME(23,0,0)),1,0)) -> 0 | S56: =IF(COUNTIFS($B$1:$B$738,B55,$C$1:$C$738,#REF!)>2,1,0) -> 0 | T56: =IF(P55>0.4,1,0) -> 0 | U56: =IF(OR(F55="Gambling",F55="ATM Withdrawal"),1,0) -> 0 | V56: =IF(OR(I56="Card Not Present (Phone)",I56="Online"),1,0) -> 1 | W56: =SUM(Q56:V56) -> 1 | X56: {=_xlfn.IFS(W56<=1,"Low",W56=2,"Medium",W56>=3,"High")} -> Low
A57: TXN500056 | B57: CC-10004 | C57: 45699 | D57: 20:29 | E57: Amazon | F57: Online Retail | G57: Johannesburg | H57: 752.19 | I57: Online | J57: Approved | K57: chargeback initiated | L57: =PROPER(TRIM(SUBSTITUTE(_xlfn.XLOOKUP(B57,Cardholders_Reference!A:A,Cardholders_Reference!B:B),","," "))) -> Rachel Sithole | M57: =_xlfn.XLOOKUP(B57,Cardholders_Reference!A:A,Cardholders_Reference!G:G) -> 20000 | N57: =_xlfn.XLOOKUP(B57,Cardholders_Reference!A:A,Cardholders_Reference!D:D) -> FNB | O57: =_xlfn.XLOOKUP(B57,Cardholders_Reference!A:A,Cardholders_Reference!E:E) -> Mastercard | P57: =H57/M57 -> 0.0376095 | Q57: =IF(COUNTIFS($B$1:$B$738,B56,$G$1:$G$738,G56)/COUNTIF($B$1:$B$738,B56)<0.5,1,0) -> 0 | R57: =IF(D57="Unknown",1,IF(OR(TIMEVALUE(D57)<TIME(5,0,0),TIMEVALUE(D57)>=TIME(23,0,0)),1,0)) -> 0 | S57: =IF(COUNTIFS($B$1:$B$738,B56,$C$1:$C$738,#REF!)>2,1,0) -> 0 | T57: =IF(P56>0.4,1,0) -> 0 | U57: =IF(OR(F56="Gambling",F56="ATM Withdrawal"),1,0) -> 1 | V57: =IF(OR(I57="Card Not Present (Phone)",I57="Online"),1,0) -> 1 | W57: =SUM(Q57:V57) -> 2 | X57: {=_xlfn.IFS(W57<=1,"Low",W57=2,"Medium",W57>=3,"High")} -> Medium
A58: TXN500057 | B58: CC-10004 | C58: 46147 | D58: 09:25 | E58: Uber Eats | F58: Restaurant | G58: Johannesburg | H58: 633.84 | I58: Online | J58: Approved | L58: =PROPER(TRIM(SUBSTITUTE(_xlfn.XLOOKUP(B58,Cardholders_Reference!A:A,Cardholders_Reference!B:B),","," "))) -> Rachel Sithole | M58: =_xlfn.XLOOKUP(B58,Cardholders_Reference!A:A,Cardholders_Reference!G:G) -> 20000 | N58: =_xlfn.XLOOKUP(B58,Cardholders_Reference!A:A,Cardholders_Reference!D:D) -> FNB | O58: =_xlfn.XLOOKUP(B58,Cardholders_Reference!A:A,Cardholders_Reference!E:E) -> Mastercard | P58: =H58/M58 -> 0.031692 | Q58: =IF(COUNTIFS($B$1:$B$738,B57,$G$1:$G$738,G57)/COUNTIF($B$1:$B$738,B57)<0.5,1,0) -> 0 | R58: =IF(D58="Unknown",1,IF(OR(TIMEVALUE(D58)<TIME(5,0,0),TIMEVALUE(D58)>=TIME(23,0,0)),1,0)) -> 0 | S58: =IF(COUNTIFS($B$1:$B$738,B57,$C$1:$C$738,#REF!)>2,1,0) -> 0 | T58: =IF(P57>0.4,1,0) -> 0 | U58: =IF(OR(F57="Gambling",F57="ATM Withdrawal"),1,0) -> 0 | V58: =IF(OR(I58="Card Not Present (Phone)",I58="Online"),1,0) -> 1 | W58: =SUM(Q58:V58) -> 1 | X58: {=_xlfn.IFS(W58<=1,"Low",W58=2,"Medium",W58>=3,"High")} -> Low
A59: TXN500058 | B59: CC-10004 | C59: 45872 | D59: 18:19 | E59: Amazon | F59: Online Retail | G59: Johannesburg | H59: 2716.48 | I59: Card Present | J59: Approved | L59: =PROPER(TRIM(SUBSTITUTE(_xlfn.XLOOKUP(B59,Cardholders_Reference!A:A,Cardholders_Reference!B:B),","," "))) -> Rachel Sithole | M59: =_xlfn.XLOOKUP(B59,Cardholders_Reference!A:A,Cardholders_Reference!G:G) -> 20000 | N59: =_xlfn.XLOOKUP(B59,Cardholders_Reference!A:A,Cardholders_Reference!D:D) -> FNB | O59: =_xlfn.XLOOKUP(B59,Cardholders_Reference!A:A,Cardholders_Reference!E:E) -> Mastercard | P59: =H59/M59 -> 0.135824 | Q59: =IF(COUNTIFS($B$1:$B$738,B58,$G$1:$G$738,G58)/COUNTIF($B$1:$B$738,B58)<0.5,1,0) -> 0 | R59: =IF(D59="Unknown",1,IF(OR(TIMEVALUE(D59)<TIME(5,0,0),TIMEVALUE(D59)>=TIME(23,0,0)),1,0)) -> 0 | S59: =IF(COUNTIFS($B$1:$B$738,B58,$C$1:$C$738,#REF!)>2,1,0) -> 0 | T59: =IF(P58>0.4,1,0) -> 0 | U59: =IF(OR(F58="Gambling",F58="ATM Withdrawal"),1,0) -> 0 | V59: =IF(OR(I59="Card Not Present (Phone)",I59="Online"),1,0) -> 0 | W59: =SUM(Q59:V59) -> 0 | X59: {=_xlfn.IFS(W59<=1,"Low",W59=2,"Medium",W59>=3,"High")} -> Low
A60: TXN500059 | B60: CC-10004 | C60: 46035 | D60: 08:13 | E60: Incredible Connection | F60: Electronics | G60: Johannesburg | H60: 8903.29 | I60: Contactless | J60: Approved | L60: =PROPER(TRIM(SUBSTITUTE(_xlfn.XLOOKUP(B60,Cardholders_Reference!A:A,Cardholders_Reference!B:B),","," "))) -> Rachel Sithole | M60: =_xlfn.XLOOKUP(B60,Cardholders_Reference!A:A,Cardholders_Reference!G:G) -> 20000 | N60: =_xlfn.XLOOKUP(B60,Cardholders_Reference!A:A,Cardholders_Reference!D:D) -> FNB | O60: =_xlfn.XLOOKUP(B60,Cardholders_Reference!A:A,Cardholders_Reference!E:E) -> Mastercard | P60: =H60/M60 -> 0.4451645 | Q60: =IF(COUNTIFS($B$1:$B$738,B59,$G$1:$G$738,G59)/COUNTIF($B$1:$B$738,B59)<0.5,1,0) -> 0 | R60: =IF(D60="Unknown",1,IF(OR(TIMEVALUE(D60)<TIME(5,0,0),TIMEVALUE(D60)>=TIME(23,0,0)),1,0)) -> 0 | S60: =IF(COUNTIFS($B$1:$B$738,B59,$C$1:$C$738,#REF!)>2,1,0) -> 0 | T60: =IF(P59>0.4,1,0) -> 0 | U60: =IF(OR(F59="Gambling",F59="ATM Withdrawal"),1,0) -> 0 | V60: =IF(OR(I60="Card Not Present (Phone)",I60="Online"),1,0) -> 0 | W60: =SUM(Q60:V60) -> 0 | X60: {=_xlfn.IFS(W60<=1,"Low",W60=2,"Medium",W60>=3,"High")} -> Low
A61: TXN500060 | B61: CC-10004 | C61: 45836 | D61: 22:13 | E61: Uber Eats | F61: Restaurant | G61: Johannesburg | H61: 286.81 | I61: Card Not Present (Phone) | J61: Declined | L61: =PROPER(TRIM(SUBSTITUTE(_xlfn.XLOOKUP(B61,Cardholders_Reference!A:A,Cardholders_Reference!B:B),","," "))) -> Rachel Sithole | M61: =_xlfn.XLOOKUP(B61,Cardholders_Reference!A:A,Cardholders_Reference!G:G) -> 20000 | N61: =_xlfn.XLOOKUP(B61,Cardholders_Reference!A:A,Cardholders_Reference!D:D) -> FNB | O61: =_xlfn.XLOOKUP(B61,Cardholders_Reference!A:A,Cardholders_Reference!E:E) -> Mastercard | P61: =H61/M61 -> 0.0143405 | Q61: =IF(COUNTIFS($B$1:$B$738,B60,$G$1:$G$738,G60)/COUNTIF($B$1:$B$738,B60)<0.5,1,0) -> 0 | R61: =IF(D61="Unknown",1,IF(OR(TIMEVALUE(D61)<TIME(5,0,0),TIMEVALUE(D61)>=TIME(23,0,0)),1,0)) -> 0 | S61: =IF(COUNTIFS($B$1:$B$738,B60,$C$1:$C$738,#REF!)>2,1,0) -> 0 | T61: =IF(P60>0.4,1,0) -> 1 | U61: =IF(OR(F60="Gambling",F60="ATM Withdrawal"),1,0) -> 0 | V61: =IF(OR(I61="Card Not Present (Phone)",I61="Online"),1,0) -> 1 | W61: =SUM(Q61:V61) -> 2 | X61: {=_xlfn.IFS(W61<=1,"Low",W61=2,"Medium",W61>=3,"High")} -> Medium
A62: TXN500061 | B62: CC-10004 | C62: 45847 | D62: 10:23 | E62: Woolworths | F62: Grocery | G62: Johannesburg | H62: 1343.7 | I62: Card Present | J62: Approved | L62: =PROPER(TRIM(SUBSTITUTE(_xlfn.XLOOKUP(B62,Cardholders_Reference!A:A,Cardholders_Reference!B:B),","," "))) -> Rachel Sithole | M62: =_xlfn.XLOOKUP(B62,Cardholders_Reference!A:A,Cardholders_Reference!G:G) -> 20000 | N62: =_xlfn.XLOOKUP(B62,Cardholders_Reference!A:A,Cardholders_Reference!D:D) -> FNB | O62: =_xlfn.XLOOKUP(B62,Cardholders_Reference!A:A,Cardholders_Reference!E:E) -> Mastercard | P62: =H62/M62 -> 0.067185 | Q62: =IF(COUNTIFS($B$1:$B$738,B61,$G$1:$G$738,G61)/COUNTIF($B$1:$B$738,B61)<0.5,1,0) -> 1 | R62: =IF(D62="Unknown",1,IF(OR(TIMEVALUE(D62)<TIME(5,0,0),TIMEVALUE(D62)>=TIME(23,0,0)),1,0)) -> 0 | S62: =IF(COUNTIFS($B$1:$B$738,B61,$C$1:$C$738,#REF!)>2,1,0) -> 0 | T62: =IF(P61>0.4,1,0) -> 0 | U62: =IF(OR(F61="Gambling",F61="ATM Withdrawal"),1,0) -> 0 | V62: =IF(OR(I62="Card Not Present (Phone)",I62="Online"),1,0) -> 0 | W62: =SUM(Q62:V62) -> 1 | X62: {=_xlfn.IFS(W62<=1,"Low",W62=2,"Medium",W62>=3,"High")} -> Low
A63: TXN500062 | B63: CC-10005 | C63: 45911 | D63: 08:19 | E63: Incredible Connection | F63: Electronics | G63: Cape Town | H63: 3140.21 | I63: Online | J63: Approved | L63: =PROPER(TRIM(SUBSTITUTE(_xlfn.XLOOKUP(B63,Cardholders_Reference!A:A,Cardholders_Reference!B:B),","," "))) -> Sanele Fourie | M63: =_xlfn.XLOOKUP(B63,Cardholders_Reference!A:A,Cardholders_Reference!G:G) -> 20000 | N63: =_xlfn.XLOOKUP(B63,Cardholders_Reference!A:A,Cardholders_Reference!D:D) -> Nedbank | O63: =_xlfn.XLOOKUP(B63,Cardholders_Reference!A:A,Cardholders_Reference!E:E) -> Mastercard | P63: =H63/M63 -> 0.1570105 | Q63: =IF(COUNTIFS($B$1:$B$738,B62,$G$1:$G$738,G62)/COUNTIF($B$1:$B$738,B62)<0.5,1,0) -> 0 | R63: =IF(D63="Unknown",1,IF(OR(TIMEVALUE(D63)<TIME(5,0,0),TIMEVALUE(D63)>=TIME(23,0,0)),1,0)) -> 0 | S63: =IF(COUNTIFS($B$1:$B$738,B62,$C$1:$C$738,#REF!)>2,1,0) -> 0 | T63: =IF(P62>0.4,1,0) -> 0 | U63: =IF(OR(F62="Gambling",F62="ATM Withdrawal"),1,0) -> 0 | V63: =IF(OR(I63="Card Not Present (Phone)",I63="Online"),1,0) -> 1 | W63: =SUM(Q63:V63) -> 1 | X63: {=_xlfn.IFS(W63<=1,"Low",W63=2,"Medium",W63>=3,"High")} -> Low
A64: TXN500063 | B64: CC-10005 | C64: 46147 | D64: 15:20 | E64: Telkom | F64: Utilities | G64: Cape Town | H64: 1860.93 | I64: Contactless | J64: Approved | L64: =PROPER(TRIM(SUBSTITUTE(_xlfn.XLOOKUP(B64,Cardholders_Reference!A:A,Cardholders_Reference!B:B),","," "))) -> Sanele Fourie | M64: =_xlfn.XLOOKUP(B64,Cardholders_Reference!A:A,Cardholders_Reference!G:G) -> 20000 | N64: =_xlfn.XLOOKUP(B64,Cardholders_Reference!A:A,Cardholders_Reference!D:D) -> Nedbank | O64: =_xlfn.XLOOKUP(B64,Cardholders_Reference!A:A,Cardholders_Reference!E:E) -> Mastercard | P64: =H64/M64 -> 0.0930465 | Q64: =IF(COUNTIFS($B$1:$B$738,B63,$G$1:$G$738,G63)/COUNTIF($B$1:$B$738,B63)<0.5,1,0) -> 0 | R64: =IF(D64="Unknown",1,IF(OR(TIMEVALUE(D64)<TIME(5,0,0),TIMEVALUE(D64)>=TIME(23,0,0)),1,0)) -> 0 | S64: =IF(COUNTIFS($B$1:$B$738,B63,$C$1:$C$738,#REF!)>2,1,0) -> 0 | T64: =IF(P63>0.4,1,0) -> 0 | U64: =IF(OR(F63="Gambling",F63="ATM Withdrawal"),1,0) -> 0 | V64: =IF(OR(I64="Card Not Present (Phone)",I64="Online"),1,0) -> 0 | W64: =SUM(Q64:V64) -> 0 | X64: {=_xlfn.IFS(W64<=1,"Low",W64=2,"Medium",W64>=3,"High")} -> Low
A65: TXN500064 | B65: CC-10005 | C65: 46001 | D65: 18:39 | E65: Engen | F65: Fuel | G65: Cape Town | H65: 809.34 | I65: Card Not Present (Phone) | J65: Approved | L65: =PROPER(TRIM(SUBSTITUTE(_xlfn.XLOOKUP(B65,Cardholders_Reference!A:A,Cardholders_Reference!B:B),","," "))) -> Sanele Fourie | M65: =_xlfn.XLOOKUP(B65,Cardholders_Reference!A:A,Cardholders_Reference!G:G) -> 20000 | N65: =_xlfn.XLOOKUP(B65,Cardholders_Reference!A:A,Cardholders_Reference!D:D) -> Nedbank | O65: =_xlfn.XLOOKUP(B65,Cardholders_Reference!A:A,Cardholders_Reference!E:E) -> Mastercard | P65: =H65/M65 -> 0.040467 | Q65: =IF(COUNTIFS($B$1:$B$738,B64,$G$1:$G$738,G64)/COUNTIF($B$1:$B$738,B64)<0.5,1,0) -> 0 | R65: =IF(D65="Unknown",1,IF(OR(TIMEVALUE(D65)<TIME(5,0,0),TIMEVALUE(D65)>=TIME(23,0,0)),1,0)) -> 0 | S65: =IF(COUNTIFS($B$1:$B$738,B64,$C$1:$C$738,#REF!)>2,1,0) -> 0 | T65: =IF(P64>0.4,1,0) -> 0 | U65: =IF(OR(F64="Gambling",F64="ATM Withdrawal"),1,0) -> 0 | V65: =IF(OR(I65="Card Not Present (Phone)",I65="Online"),1,0) -> 1 | W65: =SUM(Q65:V65) -> 1 | X65: {=_xlfn.IFS(W65<=1,"Low",W65=2,"Medium",W65>=3,"High")} -> Low
A66: TXN500065 | B66: CC-10005 | C66: 45999 | D66: 15:05 | E66: Mr Price | F66: Clothing | G66: Cape Town | H66: 1842.21 | I66: Card Not Present (Phone) | J66: Approved | L66: =PROPER(TRIM(SUBSTITUTE(_xlfn.XLOOKUP(B66,Cardholders_Reference!A:A,Cardholders_Reference!B:B),","," "))) -> Sanele Fourie | M66: =_xlfn.XLOOKUP(B66,Cardholders_Reference!A:A,Cardholders_Reference!G:G) -> 20000 | N66: =_xlfn.XLOOKUP(B66,Cardholders_Reference!A:A,Cardholders_Reference!D:D) -> Nedbank | O66: =_xlfn.XLOOKUP(B66,Cardholders_Reference!A:A,Cardholders_Reference!E:E) -> Mastercard | P66: =H66/M66 -> 0.0921105 | Q66: =IF(COUNTIFS($B$1:$B$738,B65,$G$1:$G$738,G65)/COUNTIF($B$1:$B$738,B65)<0.5,1,0) -> 0 | R66: =IF(D66="Unknown",1,IF(OR(TIMEVALUE(D66)<TIME(5,0,0),TIMEVALUE(D66)>=TIME(23,0,0)),1,0)) -> 0 | S66: =IF(COUNTIFS($B$1:$B$738,B65,$C$1:$C$738,#REF!)>2,1,0) -> 0 | T66: =IF(P65>0.4,1,0) -> 0 | U66: =IF(OR(F65="Gambling",F65="ATM Withdrawal"),1,0) -> 0 | V66: =IF(OR(I66="Card Not Present (Phone)",I66="Online"),1,0) -> 1 | W66: =SUM(Q66:V66) -> 1 | X66: {=_xlfn.IFS(W66<=1,"Low",W66=2,"Medium",W66>=3,"High")} -> Low
A67: TXN500066 | B67: CC-10005 | C67: 45854 | D67: 12:22 | E67: Avis | F67: Travel | G67: Cape Town | H67: 10964.15 | I67: Online | J67: Approved | L67: =PROPER(TRIM(SUBSTITUTE(_xlfn.XLOOKUP(B67,Cardholders_Reference!A:A,Cardholders_Reference!B:B),","," "))) -> Sanele Fourie | M67: =_xlfn.XLOOKUP(B67,Cardholders_Reference!A:A,Cardholders_Reference!G:G) -> 20000 | N67: =_xlfn.XLOOKUP(B67,Cardholders_Reference!A:A,Cardholders_Reference!D:D) -> Nedbank | O67: =_xlfn.XLOOKUP(B67,Cardholders_Reference!A:A,Cardholders_Reference!E:E) -> Mastercard | P67: =H67/M67 -> 0.5482075 | Q67: =IF(COUNTIFS($B$1:$B$738,B66,$G$1:$G$738,G66)/COUNTIF($B$1:$B$738,B66)<0.5,1,0) -> 0 | R67: =IF(D67="Unknown",1,IF(OR(TIMEVALUE(D67)<TIME(5,0,0),TIMEVALUE(D67)>=TIME(23,0,0)),1,0)) -> 0 | S67: =IF(COUNTIFS($B$1:$B$738,B66,$C$1:$C$738,#REF!)>2,1,0) -> 0 | T67: =IF(P66>0.4,1,0) -> 0 | U67: =IF(OR(F66="Gambling",F66="ATM Withdrawal"),1,0) -> 0 | V67: =IF(OR(I67="Card Not Present (Phone)",I67="Online"),1,0) -> 1 | W67: =SUM(Q67:V67) -> 1 | X67: {=_xlfn.IFS(W67<=1,"Low",W67=2,"Medium",W67>=3,"High")} -> Low
A68: TXN500067 | B68: CC-10005 | C68: 45670 | D68: 10:23 | E68: Spotify | F68: Subscription Services | G68: Cape Town | H68: 277.4 | I68: Card Not Present (Phone) | J68: Approved | K68: chargeback initiated | L68: =PROPER(TRIM(SUBSTITUTE(_xlfn.XLOOKUP(B68,Cardholders_Reference!A:A,Cardholders_Reference!B:B),","," "))) -> Sanele Fourie | M68: =_xlfn.XLOOKUP(B68,Cardholders_Reference!A:A,Cardholders_Reference!G:G) -> 20000 | N68: =_xlfn.XLOOKUP(B68,Cardholders_Reference!A:A,Cardholders_Reference!D:D) -> Nedbank | O68: =_xlfn.XLOOKUP(B68,Cardholders_Reference!A:A,Cardholders_Reference!E:E) -> Mastercard | P68: =H68/M68 -> 0.01387 | Q68: =IF(COUNTIFS($B$1:$B$738,B67,$G$1:$G$738,G67)/COUNTIF($B$1:$B$738,B67)<0.5,1,0) -> 1 | R68: =IF(D68="Unknown",1,IF(OR(TIMEVALUE(D68)<TIME(5,0,0),TIMEVALUE(D68)>=TIME(23,0,0)),1,0)) -> 0 | S68: =IF(COUNTIFS($B$1:$B$738,B67,$C$1:$C$738,#REF!)>2,1,0) -> 0 | T68: =IF(P67>0.4,1,0) -> 1 | U68: =IF(OR(F67="Gambling",F67="ATM Withdrawal"),1,0) -> 0 | V68: =IF(OR(I68="Card Not Present (Phone)",I68="Online"),1,0) -> 1 | W68: =SUM(Q68:V68) -> 3 | X68: {=_xlfn.IFS(W68<=1,"Low",W68=2,"Medium",W68>=3,"High")} -> High
...

Sheet Cardholders_Reference
A1: Cardholder Reference - Account Master Extract
A2: Source: Core Banking System Export | For internal fraud review use only
A4: Card_ID | B4: Cardholder Name | C4: City | D4: Bank | E4: Card_Network | F4: Account_Open_Date | G4: Credit_Limit
A5: CC-10000 | B5: Carlos Maseko | C5: Gqeberha | D5: Capitec | E5: Mastercard | F5: 45206 | G5: 25000
A6: CC-10001 | B6: Fatima Adams | C6: Gqeberha | D6: Standard Bank | E6: Visa | F6: 44686 | G6: 20000
A7: CC-10002 | B7: Mahlangu Lerato | C7: Pretoria | D7: Capitec | E7: Visa | F7: 45318 | G7: 100000
A8: CC-10003 | B8: Lerato Dlamini | C8: Cape Town | D8: Nedbank | E8: Visa | F8: 44727 | G8: 30000
A9: CC-10004 | B9: Rachel Sithole | C9: Johannesburg | D9: FNB | E9: Mastercard | F9: 43664 | G9: 20000
A10: CC-10005 | B10: Sanele Fourie | C10: Cape Town | D10: Nedbank | E10: Mastercard | F10: 42054 | G10: 20000
A11: CC-10006 | B11: Rachel Pretorius | C11: Johannesburg | D11: FNB | E11: Visa | F11: 43192 | G11: 80000
A12: CC-10007 | B12: Bongani Pretorius | C12: Johannesburg | D12: Nedbank | E12: Visa | F12: 43619 | G12: 40000
A13: CC-10008 | B13: Fourie Lindiwe | C13: Johannesburg | D13: Standard Bank | E13: Visa | F13: 42371 | G13: 80000
A14: CC-10009 | B14: Aisha Adams | C14: Gqeberha | D14: Standard Bank | E14: Mastercard | F14: 45630 | G14: 25000
A15: CC-10010 | B15: Bongani Nkosi | C15: Pretoria | D15: Capitec | E15: Visa | F15: 42830 | G15: 40000
A16: CC-10011 | B16: Thabo Dlamini | C16: Cape Town | D16: Capitec | E16: Visa | F16: 42070 | G16: 80000
... A66: CC-10002 | B66: Mahlangu Lerato | C66: Pretoria | D66: Capitec | E66: Visa | F66: 45318 | G66: 100000

Sheet Issues log
A1: Table | B1: Column | C1: Issue | D1: Rows | E1: Solvable | F1: Resolution
A2: Transactions_Cleaned | B2: Date | C2: Mixed date formats in Date column (dd/mm/yyyy strings + Excel datetime objects) | D2: 362 | E2: Yes | F2: Rebuilt dates manually using DATE/VALUE, standardized to single format
A3: Transactions_Cleaned | B3: Time | C3: Column consisted of blank rows | D3: 43 | E3: No | F3: timestamp for some transactionsFilled blanks with "Unknown" placeholder to preserve row count and flag for downstream logic
A4: Transactions_Cleaned | B4: City | C4: Several city names were captured in abbreviated form (e.g., “PE”, “PTA”, “JHB”, “CPT”, “Bloem”) instead of full names | D4: 278 | E4: Yes | F4: Applied the IF formula. This ensures all city names are consistently formatted in proper case.
A5: Transactions_Cleaned | B5: Amount | C5: Currency values stored as text with "R" and "ZAR" symbol and commas | D5: 90 | E5: Yes | F5: Applied the IF formula to fix the incosistent formatting
A6: Cardholders_Reference | B6: City | C6: Several city names were captured in abbreviated form (e.g., “PE”, “PTA”, “JHB”, “CPT”, “Bloem”) instead of full names | D6: 23 | E6: Yes | F6: Applied the IF formula. This ensures all city names are consistently formatted in proper case.
A7: Cardholders_Reference | B7: Date | C7: Mixed date formats in Date column (dd/mm/yyyy strings + Excel datetime objects) | D7: 31 | E7: Yes | F7: Rebuilt dates manually using DATE/VALUE, standardized to single format
A8: Cardholders_Reference | B8: Amount | C8: Currency values stored as text with "R" symbol and commas | D8: 5 | E8: Yes | F8: Applied the IF formula to fix the incosistent formatting
